<?xml version="1.0" ?>
<robot name="MZ04_01">

    <material name="black">
        <color rgba="0 0 0 1"/>
    </material>

    <material name="white">
        <color rgba="1 1 1 1"/>
    </material>

    <material name="grey">
        <color rgba="0.8 0.8 0.8 1"/>
    </material>

  <link name="base_link">
    <visual>
      <geometry>
        <mesh filename="../meshes/base_link.STL"/>
      </geometry>
      <material name="grey"/>
    </visual>
    <collision>
      <geometry>
        <mesh filename="../meshes/base_link.STL"/>
      </geometry>
    </collision>
    <inertial>
      <mass value="0.0038106"/>
      <origin rpy="0 0 0" xyz="-0.04806 -0.00017686 0.085379"/>
      <inertia ixx="1.4012E-05" ixy="-5.6304E-08" ixz="-5.6097E-07" iyy="1.8316E-05" iyz="-2.3441E-08" izz="1.5492E-05"/>
    </inertial>
  </link>

  <joint name="joint1" type="revolute">
    <parent link="base_link"/>
    <child link="link1"/>
    <origin rpy="0 0 0" xyz="0 0 0.171"/>
    <axis xyz="0 0 1"/>
    <limit effort="900000.0" lower="-500" upper="500" velocity="3.15"/>
    <dynamics damping="0.0" friction="0.0"/>
  </joint>

  <link name="link1">
    <visual>
      <geometry>
        <mesh filename="../meshes/link1.STL"/>
      </geometry>
      <material name="white"/>
    </visual>
    <collision>
      <geometry>
        <mesh filename="../meshes/link1.STL"/>
      </geometry>
    </collision>
    <inertial>
      <mass value="0.0032554"/>
      <origin rpy="0 0 0" xyz="-0.020177 0.0019738 0.086874"/>
      <inertia ixx="2.1917E-05" ixy="-1.2183E-07" ixz="-1.8701E-06" iyy="1.5329E-05" iyz="-5.5929E-07" izz="1.488E-05" />
    </inertial>
  </link>

  <joint name="joint2" type="revolute">
    <parent link="link1"/>
    <child link="link2"/>
    <origin rpy="1.5708 -0.60586 0" xyz="1.2477E-05 0.0325 0.16898"/>
    <axis xyz="0 0 1"/>
    <limit effort="900000.0" lower="-500" upper="500" velocity="3.15"/>
    <dynamics damping="0.0" friction="0.0"/>
  </joint>

  <link name="link2">
    <visual>
      <geometry>
        <mesh filename="../meshes/link2.STL"/>
      </geometry>
      <material name="white"/>
    </visual>
    <collision>
      <geometry>
        <mesh filename="../meshes/link2.STL"/>
      </geometry>
    </collision>
    <inertial>
      <mass value="0.0035927"/>
      <origin rpy="0 0 0" xyz="0.057892 0.12212 0.033537"/>
      <inertia ixx="3.2288E-05" ixy="-1.2019E-05" ixz="5.9552E-07" iyy="2.284E-05" iyz="1.0211E-06" izz="3.2854E-05" />
    </inertial>
  </link>

  <joint name="joint3" type="revolute">
    <parent link="link2"/>
    <child link="link3"/>
    <origin rpy="0 0 -0.60586" xyz="0.14806 0.21374 -0.021"/>
    <axis xyz="0 0 -1"/>
    <limit effort="900000.0" lower="-500" upper="500" velocity="3.15"/>
    <dynamics damping="0.0" friction="0.0"/>
  </joint>

  <link name="link3">
    <visual>
      <geometry>
        <mesh filename="../meshes/link3.STL"/>
      </geometry>
      <material name="white"/>
    </visual>
    <collision>
      <geometry>
        <mesh filename="../meshes/link3.STL"/>
      </geometry>
    </collision>
    <inertial>
      <mass value="0.0016486"/>
      <origin rpy="0 0 0" xyz="0.00081079 0.0066441 0.055384"/>
      <inertia ixx="2.8978E-06" ixy="-3.4122E-07" ixz="-1.5682E-08" iyy="4.3975E-06" iyz="1.679E-08" izz="5.3057E-06" />
    </inertial>
  </link>

  <joint name="joint4" type="revolute">
    <parent link="link3"/>
    <child link="link4"/>
    <origin rpy="-1.5708 0 -1.5708" xyz="0.081 0.025 0.0535"/>
    <axis xyz="0 0 1"/>
    <limit effort="900000.0" lower="-500" upper="500" velocity="3.15"/>
    <dynamics damping="0.0" friction="0.0"/>
  </joint>

  <link name="link4">
    <visual>
      <geometry>
        <mesh filename="../meshes/link4.STL"/>
      </geometry>
      <material name="white"/>
    </visual>
    <collision>
      <geometry>
        <mesh filename="../meshes/link4.STL"/>
      </geometry>
    </collision>
    <inertial>
      <mass value="0.0016679"/>
      <origin rpy="0 0 0" xyz="-0.0031849 0.00029076 0.094341"/>
      <inertia ixx="7.9985E-06" ixy="-2.4468E-09" ixz="-8.3591E-08" iyy="6.5617E-06" iyz="-5.2524E-08" izz="3.3489E-06" />
    </inertial>
  </link>

  <joint name="joint5" type="revolute">
    <parent link="link4"/>
    <child link="link5"/>
    <origin rpy="1.5708 -1.5708 0" xyz="0 0.0385 0.199"/>
    <axis xyz="0 0 1"/>
    <limit effort="900000.0" lower="-500" upper="500" velocity="3.15"/>
    <dynamics damping="0.0" friction="0.0"/>
  </joint>

  <link name="link5">
    <visual>
      <geometry>
        <mesh filename="../meshes/link5.STL"/>
      </geometry>
      <material name="white"/>
    </visual>
    <collision>
      <geometry>
        <mesh filename="../meshes/link5.STL"/>
      </geometry>
    </collision>
    <inertial>
      <mass value="0.00032008"/>
      <origin rpy="0 0 0" xyz="0.021023 -6.1204E-05 0.040338"/>
      <inertia ixx="2.9436E-07" ixy="2.4376E-10" ixz="1.2339E-08" iyy="3.9932E-07" iyz="-5.4112E-10" izz="3.4054E-07" />
    </inertial>
  </link>

  <joint name="joint6" type="revolute">
    <parent link="link5"/>
    <child link="link6"/>
    <origin rpy="-1.5708 0 -1.5708" xyz="0.072 0 0.0385"/>
    <axis xyz="0 0 -1"/>
    <limit effort="900000.0" lower="-500" upper="500" velocity="3.15"/>
    <dynamics damping="0.0" friction="0.0"/>
  </joint>

  <link name="link6">
    <visual>
      <geometry>
        <mesh filename="../meshes/link6.STL"/>
      </geometry>
      <material name="grey"/>
    </visual>
    <collision>
      <geometry>
        <mesh filename="../meshes/link6.STL"/>
      </geometry>
    </collision>
    <inertial>
      <mass value="0.0001"/>
      <origin rpy="0 0 0" xyz="-0.000193 -0.00031613 -0.0033759"/>
      <inertia ixx="9.5313E-09" ixy="5.2782E-11" ixz="-1.1636E-12" iyy="9.3769E-09" iyz="5.6536E-13" izz="1.7172E-08" />
    </inertial>
  </link>

  <joint name="joint7" type="prismatic">
    <parent link="link6"/>
    <child link="link7"/>
    <origin rpy="1.5708 0 3.14" xyz="0 -0.03235 0.08964"/>
    <axis xyz="0 0 1"/>
    <limit effort="900000.0" lower="-0.015" upper="0.015" velocity="3.15"/>
    <dynamics damping="0.0" friction="0.0"/>
  </joint>

  <link concave="yes" name="link7">
    <contact>
      <friction_anchor/>
      <stiffness value="30000.0"/>
      <damping value="1000.0"/>
      <spinning_friction value="1"/>
      <lateral_friction value="5"/>
    </contact>
    <visual>
      <geometry>
        <mesh filename="../meshes/link7.STL"/>
      </geometry>
      <material name="grey"/>
    </visual>
    <collision concave="yes">
      <geometry>
        <mesh filename="../meshes/link7.STL"/>
      </geometry>
    </collision>
    <inertial>
      <mass value="0.01"/>
      <origin rpy="0 0 0" xyz="-1.1102E-16 0.012516 -0.0087153"/>
      <inertia ixx="1.38424828450493E-07" ixy="0" ixz="0" iyy="6.94948616530377E-07" iyz="0" izz="6.59668421181749E-07"/>
    </inertial>
  </link>

  <joint name="joint8" type="prismatic">
    <parent link="link7"/>
    <child link="link8"/>
    <origin rpy="0 3.14 0" xyz="0 0 0.0647"/>
    <axis xyz="0 0 -1"/>
    <limit effort="900000.0" lower="-500" upper="500" velocity="3.15"/>
    <dynamics damping="0.0" friction="0.0"/>
  </joint>

  <link  concave="yes" name="link8">
    <contact>
      <friction_anchor/>
      <stiffness value="30000.0"/>
      <damping value="1000.0"/>
      <spinning_friction value="1"/>
      <lateral_friction value="5"/>
    </contact>
    <visual>
      <geometry>
        <mesh filename="../meshes/link8.STL"/>
      </geometry>
      <material name="grey"/>
    </visual>
    <collision concave="yes">
      <geometry>
        <mesh filename="../meshes/link8.STL"/>
      </geometry>
    </collision>
    <inertial>
      <mass value="0.01"/>
      <origin rpy="0 0 0" xyz="-1.1102E-16 0.012516 0.0087153"/>
      <inertia ixx="1.38424828450493E-07" ixy="0" ixz="0" iyy="6.94948616530376E-07" iyz="0" izz="6.59668421181747E-07" />
    </inertial>
  </link>

  <joint name="joint9" type="revolute">
    <parent link="link8"/>
    <child link="link9"/>
    <origin rpy="-1.5707963267949 0 0" xyz="0 0.0394204464167154 0.00675000000000037"/>
    <axis xyz="0 1 0"/>
    <limit effort="900000.0" lower="-500" upper="500" velocity="3.15"/>
    <dynamics damping="0.0" friction="0.0"/>
  </joint>

  <link name="link9">
    <visual>
      <geometry>
        <mesh filename="../meshes/link9.STL"/>
      </geometry>
      <material name="grey"/>
    </visual>
    <collision>
      <geometry>
        <mesh filename="../meshes/link9.STL"/>
      </geometry>
    </collision>
    <inertial>
      <mass value="1.9635E-08"/>
      <origin rpy="0 0 0" xyz="0 -5E-05 -5.5511E-17"/>
      <inertia ixx="3.2316E-16" ixy="0" ixz="0" iyy="3.2316E-16" iyz="0" izz="3.2316E-16" />
    </inertial>
  </link>


<!--################################################
  ########          connect model                #####
  ####################################################-->
  <link name="world"/>
  <joint name="world_arm_joint" type="fixed">
    <parent link="world"/>
    <child link="base_link"/>
    <origin rpy="0.0 0.0 0" xyz="0 0 0"/>
  </joint>

</robot>